

















































































































































































































































































































































































































































































































































































































































































































































































































































































































































































































































































































































































































































































































































































































































































































Epoch: 1:  29%|█████▌             | 150232/516792 [49:33<2:00:55, 50.52it/s, loss=0.0873, PSNR=19.7]
Traceback (most recent call last):
  File "H:\Deep-learning-exercises\personal implementation\thesis\train.py", line 225, in <module>
    for batch in training_dataloader:
  File "D:\Anaconda\lib\site-packages\torch\utils\data\dataloader.py", line 633, in __next__
    data = self._next_data()
  File "D:\Anaconda\lib\site-packages\torch\utils\data\dataloader.py", line 1345, in _next_data
    return self._process_data(data)
  File "D:\Anaconda\lib\site-packages\torch\utils\data\dataloader.py", line 1371, in _process_data
    data.reraise()
  File "D:\Anaconda\lib\site-packages\torch\_utils.py", line 644, in reraise
    raise exception
RuntimeError: Caught RuntimeError in DataLoader worker process 5.
Original Traceback (most recent call last):
  File "D:\Anaconda\lib\site-packages\torch\utils\data\_utils\worker.py", line 308, in _worker_loop
    data = fetcher.fetch(index)
  File "D:\Anaconda\lib\site-packages\torch\utils\data\_utils\fetch.py", line 54, in fetch
    return self.collate_fn(data)
  File "D:\Anaconda\lib\site-packages\torch\utils\data\_utils\collate.py", line 265, in default_collate
    return collate(batch, collate_fn_map=default_collate_fn_map)
  File "D:\Anaconda\lib\site-packages\torch\utils\data\_utils\collate.py", line 127, in collate
    return elem_type({key: collate([d[key] for d in batch], collate_fn_map=collate_fn_map) for key in elem})
  File "D:\Anaconda\lib\site-packages\torch\utils\data\_utils\collate.py", line 127, in <dictcomp>
    return elem_type({key: collate([d[key] for d in batch], collate_fn_map=collate_fn_map) for key in elem})
  File "D:\Anaconda\lib\site-packages\torch\utils\data\_utils\collate.py", line 119, in collate
    return collate_fn_map[elem_type](batch, collate_fn_map=collate_fn_map)
  File "D:\Anaconda\lib\site-packages\torch\utils\data\_utils\collate.py", line 160, in collate_tensor_fn
    storage = elem._typed_storage()._new_shared(numel, device=elem.device)
  File "D:\Anaconda\lib\site-packages\torch\storage.py", line 732, in _new_shared
    untyped_storage = torch.UntypedStorage._new_shared(size * self._element_size(), device=device)
  File "D:\Anaconda\lib\site-packages\torch\storage.py", line 222, in _new_shared
    return cls._new_using_filename_cpu(size)
RuntimeError: Couldn't open shared file mapping: <0000014F004D1FD2>, error code: <1455>